[2023-09-07 18:17:36 +0000] [637223] [INFO] Starting gunicorn 21.2.0
[2023-09-07 18:17:36 +0000] [637223] [INFO] Listening at: http://127.0.0.1:8000 (637223)
[2023-09-07 18:17:36 +0000] [637223] [INFO] Using worker: sync
[2023-09-07 18:17:36 +0000] [637225] [INFO] Booting worker with pid: 637225
[2023-09-08 04:48:37 +0000] [637223] [ERROR] Worker (pid:637225) was sent SIGHUP!
[2023-09-08 04:48:37 +0000] [637223] [INFO] Handling signal: hup
[2023-09-08 04:48:37 +0000] [637223] [INFO] Hang up: Master
[2023-09-08 04:48:37 +0000] [639711] [INFO] Booting worker with pid: 639711
[2023-09-08 04:48:38 +0000] [639713] [INFO] Booting worker with pid: 639713
[2023-09-08 04:49:15 +0000] [637223] [CRITICAL] WORKER TIMEOUT (pid:639711)
[2023-09-08 04:49:15 +0000] [637223] [CRITICAL] WORKER TIMEOUT (pid:639713)
[2023-09-08 04:49:15 +0000] [639713] [INFO] Worker exiting (pid: 639713)
[2023-09-08 04:49:22 +0000] [637223] [ERROR] Worker (pid:639711) was sent SIGKILL! Perhaps out of memory?
[2023-09-08 04:49:22 +0000] [637223] [ERROR] Worker (pid:639713) was sent SIGKILL! Perhaps out of memory?
[2023-09-08 04:49:22 +0000] [639720] [INFO] Booting worker with pid: 639720
[2023-09-08 06:22:09 +0000] [637223] [INFO] Handling signal: hup
--- Logging error ---
Traceback (most recent call last):
  File "/usr/lib/python3.8/logging/__init__.py", line 1089, in emit
    self.flush()
  File "/usr/lib/python3.8/logging/__init__.py", line 1069, in flush
    self.stream.flush()
RuntimeError: reentrant call inside <_io.BufferedWriter name='<stderr>'>
Call stack:
  File "/home/ubuntu/RecipeMuse/myprojectenv/bin/gunicorn", line 8, in <module>
    sys.exit(run())
  File "/home/ubuntu/RecipeMuse/myprojectenv/lib/python3.8/site-packages/gunicorn/app/wsgiapp.py", line 67, in run
    WSGIApplication("%(prog)s [OPTIONS] [APP_MODULE]").run()
  File "/home/ubuntu/RecipeMuse/myprojectenv/lib/python3.8/site-packages/gunicorn/app/base.py", line 236, in run
    super().run()
  File "/home/ubuntu/RecipeMuse/myprojectenv/lib/python3.8/site-packages/gunicorn/app/base.py", line 72, in run
    Arbiter(self).run()
  File "/home/ubuntu/RecipeMuse/myprojectenv/lib/python3.8/site-packages/gunicorn/arbiter.py", line 223, in run
    self.log.info("Handling signal: %s", signame)
  File "/home/ubuntu/RecipeMuse/myprojectenv/lib/python3.8/site-packages/gunicorn/glogging.py", line 278, in info
    self.error_log.info(msg, *args, **kwargs)
  File "/usr/lib/python3.8/logging/__init__.py", line 1446, in info
    self._log(INFO, msg, args, **kwargs)
  File "/usr/lib/python3.8/logging/__init__.py", line 1589, in _log
    self.handle(record)
  File "/usr/lib/python3.8/logging/__init__.py", line 1599, in handle
    self.callHandlers(record)
  File "/usr/lib/python3.8/logging/__init__.py", line 1661, in callHandlers
    hdlr.handle(record)
  File "/usr/lib/python3.8/logging/__init__.py", line 954, in handle
    self.emit(record)
  File "/usr/lib/python3.8/logging/__init__.py", line 1089, in emit
    self.flush()
  File "/usr/lib/python3.8/logging/__init__.py", line 1069, in flush
    self.stream.flush()
  File "/home/ubuntu/RecipeMuse/myprojectenv/lib/python3.8/site-packages/gunicorn/arbiter.py", line 242, in handle_chld
    self.reap_workers()
  File "/home/ubuntu/RecipeMuse/myprojectenv/lib/python3.8/site-packages/gunicorn/arbiter.py", line 554, in reap_workers
    self.log.error(msg)
  File "/home/ubuntu/RecipeMuse/myprojectenv/lib/python3.8/site-packages/gunicorn/glogging.py", line 272, in error
    self.error_log.error(msg, *args, **kwargs)
Message: 'Worker (pid:639720) was sent SIGHUP!'
Arguments: ()
[2023-09-08 06:22:10 +0000] [637223] [INFO] Hang up: Master
[2023-09-08 06:22:10 +0000] [637223] [INFO] Handling signal: term
[2023-09-08 06:22:10 +0000] [648643] [INFO] Booting worker with pid: 648643
[2023-09-08 06:22:40 +0000] [637223] [ERROR] Worker (pid:648643) was sent SIGKILL! Perhaps out of memory?
[2023-09-08 06:22:40 +0000] [637223] [INFO] Shutting down: Master
